[0m20:16:57.748970 [debug] [MainThread]: Sending event: {'category': 'dbt', 'action': 'invocation', 'label': 'start', 'context': [<snowplow_tracker.self_describing_json.SelfDescribingJson object at 0x00000285BD652C90>, <snowplow_tracker.self_describing_json.SelfDescribingJson object at 0x00000285BD652C50>, <snowplow_tracker.self_describing_json.SelfDescribingJson object at 0x00000285BD652E90>]}


============================== 20:16:57.757480 | aa366773-7756-4e37-b1e2-155a28dcf100 ==============================
[0m20:16:57.757480 [info ] [MainThread]: Running with dbt=1.7.0
[0m20:16:57.758480 [debug] [MainThread]: running dbt with arguments {'printer_width': '80', 'indirect_selection': 'eager', 'write_json': 'True', 'log_cache_events': 'False', 'partial_parse': 'True', 'cache_selected_only': 'False', 'warn_error': 'None', 'debug': 'False', 'profiles_dir': 'C:\\Users\\61420\\.dbt', 'log_path': 'logs', 'fail_fast': 'False', 'version_check': 'True', 'use_colors': 'True', 'use_experimental_parser': 'False', 'no_print': 'None', 'quiet': 'False', 'warn_error_options': 'WarnErrorOptions(include=[], exclude=[])', 'introspect': 'True', 'static_parser': 'True', 'invocation_command': 'dbt init', 'target_path': 'None', 'log_format': 'default', 'send_anonymous_usage_stats': 'True'}
[0m20:16:57.763013 [error] [MainThread]: Encountered an error:
[ConfigFolderDirectory]: Unable to parse dict {'dir': WindowsPath('C:/Users/61420/.dbt')}
[0m20:16:57.772569 [error] [MainThread]: Traceback (most recent call last):
  File "C:\Users\61420\anaconda3\envs\dagster\Lib\site-packages\google\protobuf\json_format.py", line 608, in _ConvertFieldValuePair
    _ConvertScalarFieldValue(value, field,
  File "C:\Users\61420\anaconda3\envs\dagster\Lib\site-packages\google\protobuf\json_format.py", line 779, in _ConvertScalarFieldValue
    if _UNPAIRED_SURROGATE_PATTERN.search(value):
       ^^^^^^^^^^^^^^^^^^^^^^^^^^^^^^^^^^^^^^^^^
TypeError: expected string or bytes-like object, got 'WindowsPath'

The above exception was the direct cause of the following exception:

Traceback (most recent call last):
  File "C:\Users\61420\anaconda3\envs\dagster\Lib\site-packages\dbt\events\base_types.py", line 72, in __init__
    self.pb_msg = ParseDict(kwargs, msg_cls())
                  ^^^^^^^^^^^^^^^^^^^^^^^^^^^^
  File "C:\Users\61420\anaconda3\envs\dagster\Lib\site-packages\google\protobuf\json_format.py", line 446, in ParseDict
    parser.ConvertMessage(js_dict, message, '')
  File "C:\Users\61420\anaconda3\envs\dagster\Lib\site-packages\google\protobuf\json_format.py", line 487, in ConvertMessage
    self._ConvertFieldValuePair(value, message, path)
  File "C:\Users\61420\anaconda3\envs\dagster\Lib\site-packages\google\protobuf\json_format.py", line 622, in _ConvertFieldValuePair
    raise ParseError(
google.protobuf.json_format.ParseError: Failed to parse dir field: expected string or bytes-like object, got 'WindowsPath'.

During handling of the above exception, another exception occurred:

Traceback (most recent call last):
  File "C:\Users\61420\anaconda3\envs\dagster\Lib\site-packages\dbt\cli\requires.py", line 90, in wrapper
    result, success = func(*args, **kwargs)
                      ^^^^^^^^^^^^^^^^^^^^^
  File "C:\Users\61420\anaconda3\envs\dagster\Lib\site-packages\dbt\cli\requires.py", line 75, in wrapper
    return func(*args, **kwargs)
           ^^^^^^^^^^^^^^^^^^^^^
  File "C:\Users\61420\anaconda3\envs\dagster\Lib\site-packages\dbt\cli\main.py", line 515, in init
    results = task.run()
              ^^^^^^^^^^
  File "C:\Users\61420\anaconda3\envs\dagster\Lib\site-packages\dbt\task\init.py", line 298, in run
    self.create_profiles_dir(profiles_dir)
  File "C:\Users\61420\anaconda3\envs\dagster\Lib\site-packages\dbt\task\init.py", line 70, in create_profiles_dir
    fire_event(ConfigFolderDirectory(dir=profiles_dir))
               ^^^^^^^^^^^^^^^^^^^^^^^^^^^^^^^^^^^^^^^
  File "C:\Users\61420\anaconda3\envs\dagster\Lib\site-packages\dbt\events\base_types.py", line 81, in __init__
    raise Exception(error_msg)
Exception: [ConfigFolderDirectory]: Unable to parse dict {'dir': WindowsPath('C:/Users/61420/.dbt')}

[0m20:16:57.777542 [debug] [MainThread]: Command `dbt init` failed at 20:16:57.777542 after 0.08 seconds
[0m20:16:57.778540 [debug] [MainThread]: Sending event: {'category': 'dbt', 'action': 'invocation', 'label': 'end', 'context': [<snowplow_tracker.self_describing_json.SelfDescribingJson object at 0x00000285BD643A10>, <snowplow_tracker.self_describing_json.SelfDescribingJson object at 0x00000285B6337A10>, <snowplow_tracker.self_describing_json.SelfDescribingJson object at 0x00000285BD653A10>]}
[0m20:16:57.778540 [debug] [MainThread]: Flushing usage events
[0m20:22:29.569538 [debug] [MainThread]: Sending event: {'category': 'dbt', 'action': 'invocation', 'label': 'start', 'context': [<snowplow_tracker.self_describing_json.SelfDescribingJson object at 0x0000017C7D522790>, <snowplow_tracker.self_describing_json.SelfDescribingJson object at 0x0000017C7D522950>, <snowplow_tracker.self_describing_json.SelfDescribingJson object at 0x0000017C7D520A10>]}


============================== 20:22:29.574507 | 0f83cf53-8f4c-4bfb-8e37-7cae459ff6a8 ==============================
[0m20:22:29.574507 [info ] [MainThread]: Running with dbt=1.7.0
[0m20:22:29.575517 [debug] [MainThread]: running dbt with arguments {'printer_width': '80', 'indirect_selection': 'eager', 'log_cache_events': 'False', 'write_json': 'True', 'partial_parse': 'True', 'cache_selected_only': 'False', 'warn_error': 'None', 'version_check': 'True', 'profiles_dir': 'C:\\Users\\61420\\.dbt', 'log_path': 'logs', 'debug': 'False', 'fail_fast': 'False', 'use_colors': 'True', 'use_experimental_parser': 'False', 'no_print': 'None', 'quiet': 'False', 'warn_error_options': 'WarnErrorOptions(include=[], exclude=[])', 'static_parser': 'True', 'introspect': 'True', 'log_format': 'default', 'target_path': 'None', 'invocation_command': 'dbt init', 'send_anonymous_usage_stats': 'True'}
[0m20:22:29.576508 [error] [MainThread]: Encountered an error:
[ConfigFolderDirectory]: Unable to parse dict {'dir': WindowsPath('C:/Users/61420/.dbt')}
[0m20:22:29.582590 [error] [MainThread]: Traceback (most recent call last):
  File "C:\Users\61420\anaconda3\envs\dagster\Lib\site-packages\google\protobuf\json_format.py", line 608, in _ConvertFieldValuePair
    _ConvertScalarFieldValue(value, field,
  File "C:\Users\61420\anaconda3\envs\dagster\Lib\site-packages\google\protobuf\json_format.py", line 779, in _ConvertScalarFieldValue
    if _UNPAIRED_SURROGATE_PATTERN.search(value):
       ^^^^^^^^^^^^^^^^^^^^^^^^^^^^^^^^^^^^^^^^^
TypeError: expected string or bytes-like object, got 'WindowsPath'

The above exception was the direct cause of the following exception:

Traceback (most recent call last):
  File "C:\Users\61420\anaconda3\envs\dagster\Lib\site-packages\dbt\events\base_types.py", line 72, in __init__
    self.pb_msg = ParseDict(kwargs, msg_cls())
                  ^^^^^^^^^^^^^^^^^^^^^^^^^^^^
  File "C:\Users\61420\anaconda3\envs\dagster\Lib\site-packages\google\protobuf\json_format.py", line 446, in ParseDict
    parser.ConvertMessage(js_dict, message, '')
  File "C:\Users\61420\anaconda3\envs\dagster\Lib\site-packages\google\protobuf\json_format.py", line 487, in ConvertMessage
    self._ConvertFieldValuePair(value, message, path)
  File "C:\Users\61420\anaconda3\envs\dagster\Lib\site-packages\google\protobuf\json_format.py", line 622, in _ConvertFieldValuePair
    raise ParseError(
google.protobuf.json_format.ParseError: Failed to parse dir field: expected string or bytes-like object, got 'WindowsPath'.

During handling of the above exception, another exception occurred:

Traceback (most recent call last):
  File "C:\Users\61420\anaconda3\envs\dagster\Lib\site-packages\dbt\cli\requires.py", line 90, in wrapper
    result, success = func(*args, **kwargs)
                      ^^^^^^^^^^^^^^^^^^^^^
  File "C:\Users\61420\anaconda3\envs\dagster\Lib\site-packages\dbt\cli\requires.py", line 75, in wrapper
    return func(*args, **kwargs)
           ^^^^^^^^^^^^^^^^^^^^^
  File "C:\Users\61420\anaconda3\envs\dagster\Lib\site-packages\dbt\cli\main.py", line 515, in init
    results = task.run()
              ^^^^^^^^^^
  File "C:\Users\61420\anaconda3\envs\dagster\Lib\site-packages\dbt\task\init.py", line 298, in run
    self.create_profiles_dir(profiles_dir)
  File "C:\Users\61420\anaconda3\envs\dagster\Lib\site-packages\dbt\task\init.py", line 70, in create_profiles_dir
    fire_event(ConfigFolderDirectory(dir=profiles_dir))
               ^^^^^^^^^^^^^^^^^^^^^^^^^^^^^^^^^^^^^^^
  File "C:\Users\61420\anaconda3\envs\dagster\Lib\site-packages\dbt\events\base_types.py", line 81, in __init__
    raise Exception(error_msg)
Exception: [ConfigFolderDirectory]: Unable to parse dict {'dir': WindowsPath('C:/Users/61420/.dbt')}

[0m20:22:29.586591 [debug] [MainThread]: Command `dbt init` failed at 20:22:29.586591 after 0.07 seconds
[0m20:22:29.587607 [debug] [MainThread]: Sending event: {'category': 'dbt', 'action': 'invocation', 'label': 'end', 'context': [<snowplow_tracker.self_describing_json.SelfDescribingJson object at 0x0000017C7D5233D0>, <snowplow_tracker.self_describing_json.SelfDescribingJson object at 0x0000017C7D523950>, <snowplow_tracker.self_describing_json.SelfDescribingJson object at 0x0000017C761F7E50>]}
[0m20:22:29.588594 [debug] [MainThread]: Flushing usage events
[0m20:26:51.119531 [debug] [MainThread]: Sending event: {'category': 'dbt', 'action': 'invocation', 'label': 'start', 'context': [<snowplow_tracker.self_describing_json.SelfDescribingJson object at 0x000002347B0C3ED0>, <snowplow_tracker.self_describing_json.SelfDescribingJson object at 0x000002347B0D1510>, <snowplow_tracker.self_describing_json.SelfDescribingJson object at 0x000002347B0D1750>]}


============================== 20:26:51.125537 | 17cff3ad-c82f-4a1a-a07f-6b45d7eed632 ==============================
[0m20:26:51.125537 [info ] [MainThread]: Running with dbt=1.7.0
[0m20:26:51.126537 [debug] [MainThread]: running dbt with arguments {'printer_width': '80', 'indirect_selection': 'eager', 'write_json': 'True', 'log_cache_events': 'False', 'partial_parse': 'True', 'cache_selected_only': 'False', 'warn_error': 'None', 'debug': 'False', 'profiles_dir': 'C:\\Users\\61420\\.dbt', 'log_path': 'logs', 'fail_fast': 'False', 'version_check': 'True', 'use_colors': 'True', 'use_experimental_parser': 'False', 'no_print': 'None', 'quiet': 'False', 'warn_error_options': 'WarnErrorOptions(include=[], exclude=[])', 'static_parser': 'True', 'invocation_command': 'dbt init', 'introspect': 'True', 'target_path': 'None', 'log_format': 'default', 'send_anonymous_usage_stats': 'True'}
[0m20:26:51.127536 [error] [MainThread]: Encountered an error:
[ConfigFolderDirectory]: Unable to parse dict {'dir': WindowsPath('C:/Users/61420/.dbt')}
[0m20:26:51.133839 [error] [MainThread]: Traceback (most recent call last):
  File "C:\Users\61420\anaconda3\envs\dagster\Lib\site-packages\google\protobuf\json_format.py", line 608, in _ConvertFieldValuePair
    _ConvertScalarFieldValue(value, field,
  File "C:\Users\61420\anaconda3\envs\dagster\Lib\site-packages\google\protobuf\json_format.py", line 779, in _ConvertScalarFieldValue
    if _UNPAIRED_SURROGATE_PATTERN.search(value):
       ^^^^^^^^^^^^^^^^^^^^^^^^^^^^^^^^^^^^^^^^^
TypeError: expected string or bytes-like object, got 'WindowsPath'

The above exception was the direct cause of the following exception:

Traceback (most recent call last):
  File "C:\Users\61420\anaconda3\envs\dagster\Lib\site-packages\dbt\events\base_types.py", line 72, in __init__
    self.pb_msg = ParseDict(kwargs, msg_cls())
                  ^^^^^^^^^^^^^^^^^^^^^^^^^^^^
  File "C:\Users\61420\anaconda3\envs\dagster\Lib\site-packages\google\protobuf\json_format.py", line 446, in ParseDict
    parser.ConvertMessage(js_dict, message, '')
  File "C:\Users\61420\anaconda3\envs\dagster\Lib\site-packages\google\protobuf\json_format.py", line 487, in ConvertMessage
    self._ConvertFieldValuePair(value, message, path)
  File "C:\Users\61420\anaconda3\envs\dagster\Lib\site-packages\google\protobuf\json_format.py", line 622, in _ConvertFieldValuePair
    raise ParseError(
google.protobuf.json_format.ParseError: Failed to parse dir field: expected string or bytes-like object, got 'WindowsPath'.

During handling of the above exception, another exception occurred:

Traceback (most recent call last):
  File "C:\Users\61420\anaconda3\envs\dagster\Lib\site-packages\dbt\cli\requires.py", line 90, in wrapper
    result, success = func(*args, **kwargs)
                      ^^^^^^^^^^^^^^^^^^^^^
  File "C:\Users\61420\anaconda3\envs\dagster\Lib\site-packages\dbt\cli\requires.py", line 75, in wrapper
    return func(*args, **kwargs)
           ^^^^^^^^^^^^^^^^^^^^^
  File "C:\Users\61420\anaconda3\envs\dagster\Lib\site-packages\dbt\cli\main.py", line 515, in init
    results = task.run()
              ^^^^^^^^^^
  File "C:\Users\61420\anaconda3\envs\dagster\Lib\site-packages\dbt\task\init.py", line 298, in run
    self.create_profiles_dir(profiles_dir)
  File "C:\Users\61420\anaconda3\envs\dagster\Lib\site-packages\dbt\task\init.py", line 70, in create_profiles_dir
    fire_event(ConfigFolderDirectory(dir=profiles_dir))
               ^^^^^^^^^^^^^^^^^^^^^^^^^^^^^^^^^^^^^^^
  File "C:\Users\61420\anaconda3\envs\dagster\Lib\site-packages\dbt\events\base_types.py", line 81, in __init__
    raise Exception(error_msg)
Exception: [ConfigFolderDirectory]: Unable to parse dict {'dir': WindowsPath('C:/Users/61420/.dbt')}

[0m20:26:51.139354 [debug] [MainThread]: Command `dbt init` failed at 20:26:51.139354 after 0.07 seconds
[0m20:26:51.140385 [debug] [MainThread]: Sending event: {'category': 'dbt', 'action': 'invocation', 'label': 'end', 'context': [<snowplow_tracker.self_describing_json.SelfDescribingJson object at 0x000002347B0DFDD0>, <snowplow_tracker.self_describing_json.SelfDescribingJson object at 0x000002347B0D2E10>, <snowplow_tracker.self_describing_json.SelfDescribingJson object at 0x000002347B0D2690>]}
[0m20:26:51.140385 [debug] [MainThread]: Flushing usage events
[0m20:29:34.082088 [debug] [MainThread]: Sending event: {'category': 'dbt', 'action': 'invocation', 'label': 'start', 'context': [<snowplow_tracker.self_describing_json.SelfDescribingJson object at 0x000001DACAA992D0>, <snowplow_tracker.self_describing_json.SelfDescribingJson object at 0x000001DACAA70A90>, <snowplow_tracker.self_describing_json.SelfDescribingJson object at 0x000001DACAC89410>]}


============================== 20:29:34.086088 | d42e1dc7-01c0-4480-b880-1687a0e2fb8f ==============================
[0m20:29:34.086088 [info ] [MainThread]: Running with dbt=1.7.0
[0m20:29:34.087610 [debug] [MainThread]: running dbt with arguments {'printer_width': '80', 'indirect_selection': 'eager', 'write_json': 'True', 'log_cache_events': 'False', 'partial_parse': 'True', 'cache_selected_only': 'False', 'profiles_dir': 'C:\\Users\\61420\\.dbt', 'version_check': 'True', 'debug': 'False', 'log_path': 'logs', 'warn_error': 'None', 'fail_fast': 'False', 'use_colors': 'True', 'use_experimental_parser': 'False', 'no_print': 'None', 'quiet': 'False', 'log_format': 'default', 'static_parser': 'True', 'introspect': 'True', 'warn_error_options': 'WarnErrorOptions(include=[], exclude=[])', 'target_path': 'None', 'invocation_command': 'dbt init -s', 'send_anonymous_usage_stats': 'True'}
[0m20:29:34.088615 [warn ] [MainThread]: [ConfigFolderDirectory]: Unable to parse dict {'dir': WindowsPath('C:/Users/61420/.dbt')}
[0m20:29:34.088615 [info ] [MainThread]: Creating dbt configuration folder at 
[0m20:29:41.277060 [debug] [MainThread]: Starter project path: C:\Users\61420\BetfairAnalysis\.venv\Lib\site-packages\dbt\include\starter_project
[0m20:29:41.323829 [info ] [MainThread]: 
Your new dbt project "testTim" was created!

For more information on how to configure the profiles.yml file,
please consult the dbt documentation here:

  https://docs.getdbt.com/docs/configure-your-profile

One more thing:

Need help? Don't hesitate to reach out to us via GitHub issues or on Slack:

  https://community.getdbt.com/

Happy modeling!

[0m20:29:41.327338 [debug] [MainThread]: Command `dbt init` succeeded at 20:29:41.327338 after 7.30 seconds
[0m20:29:41.328347 [debug] [MainThread]: Sending event: {'category': 'dbt', 'action': 'invocation', 'label': 'end', 'context': [<snowplow_tracker.self_describing_json.SelfDescribingJson object at 0x000001DACAF4DAD0>, <snowplow_tracker.self_describing_json.SelfDescribingJson object at 0x000001DAC93D52D0>, <snowplow_tracker.self_describing_json.SelfDescribingJson object at 0x000001DACA174550>]}
[0m20:29:41.328347 [debug] [MainThread]: Flushing usage events
